Traceback (most recent call last):
  File "hello_mpi.py", line 40, in <module>
    hello_mpi ( )
  File "hello_mpi.py", line 22, in hello_mpi
    from mpi4py import MPI
ModuleNotFoundError: No module named 'mpi4py'
Traceback (most recent call last):
  File "hello_mpi.py", line 40, in <module>
    hello_mpi ( )
  File "hello_mpi.py", line 22, in hello_mpi
    from mpi4py import MPI
ModuleNotFoundError: No module named 'mpi4py'
-------------------------------------------------------
Primary job  terminated normally, but 1 process returned
a non-zero exit code.. Per user-direction, the job has been aborted.
-------------------------------------------------------
Traceback (most recent call last):
  File "hello_mpi.py", line 40, in <module>
    hello_mpi ( )
  File "hello_mpi.py", line 22, in hello_mpi
    from mpi4py import MPI
ModuleNotFoundError: No module named 'mpi4py'
Traceback (most recent call last):
  File "hello_mpi.py", line 40, in <module>
    hello_mpi ( )
  File "hello_mpi.py", line 22, in hello_mpi
    from mpi4py import MPI
ModuleNotFoundError: No module named 'mpi4py'
--------------------------------------------------------------------------
mpirun detected that one or more processes exited with non-zero status, thus causing
the job to be terminated. The first process to do so was:

  Process name: [[2473,1],0]
  Exit code:    1
--------------------------------------------------------------------------
